Workbook

Sheet Principal
A1: Ativo | B1: Data | C1: Último (R$) | D1: Var. Dia (%) | E1: Var. Sem. (%) | F1: Var. Mês (%) | G1: Var. Ano (%) | H1: Var. 12M (%) | I1: Val. Máx | J1: Val. Mín | K1: Volume | L1: Variação Dia % | M1: Valor Inicial Dia(R$) | N1: Quantidade de Ações | O1: Variação Dia (R$) | P1: Resultado | Q1: Nome da empresa | R1: Segmento | S1: Idade | T1: Cat_idade | U1: Variação Sem % | V1: Valor Inicial Sem (R$) | W1: Variação Sem (R$) | X1: Resultado Sem | Y1: Variação Mês % | Z1: Valor Inicial Mês (R$) | AA1: Variação Mês (R$) | AB1: Resultado Mês | AC1: Variação Ano % | AD1: Valor Inicial Ano (R$) | AE1: Variação Ano (R$) | AF1: Resultado Ano | AG1: Variação 12M % | AH1: Valor Inicial 12M (R$) | AI1: Variação 12M (R$) | AJ1: Resultado 12M
A2: USIM5 | B2: 45317 | C2: 9.5 | D2: 5.2 | E2: 11.76 | F2: 2.26 | G2: 2.26 | H2: 15.97 | I2: 9.56 | J2: 9.18 | K2: 319,16 M | L2: =D2/100 -> 0.052 | M2: =C2/(L2+1) -> 9.0304183 | N2: =VLOOKUP(A2,'Total de Ações'!A:B,2,0) -> 515117391 | O2: =(C2-M2)*N2 -> 2.4188973e+08 | P2: =IF(O2>0,"Subiu",if(O2<0,"Desceu","Estável")) -> Subiu | Q2: =VLOOKUP(A2,Ticker!A:B,2,0) -> Usiminas | R2: =VLOOKUP(Q2,ChatGpt!A:C,2,0) -> Siderurgia | S2: =VLOOKUP(Q2,ChatGpt!A:C,3,0) -> 60 | T2: =IF(S2>100,"Mais de 100", IF(S2<50,"Menos de 50","Entre 50 e 100")) -> Entre 50 e 100 | U2: =E2/100 -> 0.1176 | V2: =C2/(U2+1) -> 8.5003579 | W2: =(C2-V2)*N2 -> 5.1493303e+08 | X2: =IF(W2>0,"Subiu",IF(W2<0,"Desceu","Estável")) -> Subiu | Y2: =F2/100 -> 0.0226 | Z2: =C2/(Y2+1) -> 9.290045 | AA2: =(C2-Z2)*N2 -> 1.0815148e+08 | AB2: =IF(AA2>0,"Subiu",(IF(AA2<0,"Desceu","Estável"))) -> Subiu | AC2: =G2/100 -> 0.0226 | AD2: =C2/(AC2+1) -> 9.290045 | AE2: =(C2-AD2)*N2 -> 1.0815148e+08 | AF2: =IF(AE2>0,"Subiu",IF(AE2<0,"Desceu","Estável")) -> Subiu | AG2: =H2/100 -> 0.1597 | AH2: =C2/(AG2+1) -> 8.1917737 | AI2: =(C2-AH2)*N2 -> 6.738901e+08 | AJ2: =IF(AI2>0,"Subiu",IF(AI2<0,"Desceu","Estável")) -> Subiu
A3: CMIN3 | B3: 45317 | C3: 6.82 | D3: 2.4 | E3: 2.4 | F3: -12.11 | G3: -12.11 | H3: 50.56 | I3: 6.86 | J3: 6.66 | K3: 32,65 M | L3: =D3/100 -> 0.024 | M3: =C3/(L3+1) -> 6.6601562 | N3: =VLOOKUP(A3,'Total de Ações'!A:B,2,0) -> 1110559345 | O3: =(C3-M3)*N3 -> 1.7751597e+08 | P3: =IF(O3>0,"Subiu",if(O3<0,"Desceu","Estável")) -> Subiu | Q3: =VLOOKUP(A3,Ticker!A:B,2,0) -> CSN Mineração | R3: =VLOOKUP(Q3,ChatGpt!A:C,2,0) -> Mineração | S3: =VLOOKUP(Q3,ChatGpt!A:C,3,0) -> 50 | T3: =IF(S3>100,"Mais de 100", IF(S3<50,"Menos de 50","Entre 50 e 100")) -> Entre 50 e 100 | U3: =E3/100 -> 0.024 | V3: =C3/(U3+1) -> 6.6601562 | W3: =(C3-V3)*N3 -> 1.7751597e+08 | X3: =IF(W3>0,"Subiu",IF(W3<0,"Desceu","Estável")) -> Subiu | Y3: =F3/100 -> -0.1211 | Z3: =C3/(Y3+1) -> 7.7596996 | AA3: =(C3-Z3)*N3 -> -1043592200 | AB3: =IF(AA3>0,"Subiu",(IF(AA3<0,"Desceu","Estável"))) -> Desceu | AC3: =G3/100 -> -0.1211 | AD3: =C3/(AC3+1) -> 7.7596996 | AE3: =(C3-AD3)*N3 -> -1043592200 | AF3: =IF(AE3>0,"Subiu",IF(AE3<0,"Desceu","Estável")) -> Desceu | AG3: =H3/100 -> 0.5056 | AH3: =C3/(AG3+1) -> 4.5297556 | AI3: =(C3-AH3)*N3 -> 2543452344 | AJ3: =IF(AI3>0,"Subiu",IF(AI3<0,"Desceu","Estável")) -> Subiu
A4: PETR3 | B4: 45317 | C4: 41.96 | D4: 2.19 | E4: 7.73 | F4: 7.64 | G4: 7.64 | H4: 77.55 | I4: 42.34 | J4: 40.81 | K4: 436,69 M | L4: =D4/100 -> 0.0219 | M4: =C4/(L4+1) -> 41.060769 | N4: =VLOOKUP(A4,'Total de Ações'!A:B,2,0) -> 2379877655 | O4: =(C4-M4)*N4 -> 2140059394 | P4: =IF(O4>0,"Subiu",if(O4<0,"Desceu","Estável")) -> Subiu | Q4: =VLOOKUP(A4,Ticker!A:B,2,0) -> Petrobras | R4: =VLOOKUP(Q4,ChatGpt!A:C,2,0) -> Petróleo e Gás | S4: =VLOOKUP(Q4,ChatGpt!A:C,3,0) -> 60 | T4: =IF(S4>100,"Mais de 100", IF(S4<50,"Menos de 50","Entre 50 e 100")) -> Entre 50 e 100 | U4: =E4/100 -> 0.0773 | V4: =C4/(U4+1) -> 38.949225 | W4: =(C4-V4)*N4 -> 7165276351 | X4: =IF(W4>0,"Subiu",IF(W4<0,"Desceu","Estável")) -> Subiu | Y4: =F4/100 -> 0.0764 | Z4: =C4/(Y4+1) -> 38.981791 | AA4: =(C4-Z4)*N4 -> 7087772680 | AB4: =IF(AA4>0,"Subiu",(IF(AA4<0,"Desceu","Estável"))) -> Subiu | AC4: =G4/100 -> 0.0764 | AD4: =C4/(AC4+1) -> 38.981791 | AE4: =(C4-AD4)*N4 -> 7087772680 | AF4: =IF(AE4>0,"Subiu",IF(AE4<0,"Desceu","Estável")) -> Subiu | AG4: =H4/100 -> 0.7755 | AH4: =C4/(AG4+1) -> 23.63278 | AI4: =(C4-AH4)*N4 -> 43616542549 | AJ4: =IF(AI4>0,"Subiu",IF(AI4<0,"Desceu","Estável")) -> Subiu
A5: SUZB3 | B5: 45317 | C5: 52.91 | D5: 2.04 | E5: 2.14 | F5: -4.89 | G5: -4.89 | H5: 18.85 | I5: 53.17 | J5: 51.89 | K5: 162,55 M | L5: =D5/100 -> 0.0204 | M5: =C5/(L5+1) -> 51.852215 | N5: =VLOOKUP(A5,'Total de Ações'!A:B,2,0) -> 683452836 | O5: =(C5-M5)*N5 -> 7.2294628e+08 | P5: =IF(O5>0,"Subiu",if(O5<0,"Desceu","Estável")) -> Subiu | Q5: =VLOOKUP(A5,Ticker!A:B,2,0) -> Suzano | R5: =VLOOKUP(Q5,ChatGpt!A:C,2,0) -> Papel e Celulose | S5: =VLOOKUP(Q5,ChatGpt!A:C,3,0) -> 90 | T5: =IF(S5>100,"Mais de 100", IF(S5<50,"Menos de 50","Entre 50 e 100")) -> Entre 50 e 100 | U5: =E5/100 -> 0.0214 | V5: =C5/(U5+1) -> 51.801449 | W5: =(C5-V5)*N5 -> 7.5764233e+08 | X5: =IF(W5>0,"Subiu",IF(W5<0,"Desceu","Estável")) -> Subiu | Y5: =F5/100 -> -0.0489 | Z5: =C5/(Y5+1) -> 55.630323 | AA5: =(C5-Z5)*N5 -> -1859212322 | AB5: =IF(AA5>0,"Subiu",(IF(AA5<0,"Desceu","Estável"))) -> Desceu | AC5: =G5/100 -> -0.0489 | AD5: =C5/(AC5+1) -> 55.630323 | AE5: =(C5-AD5)*N5 -> -1859212322 | AF5: =IF(AE5>0,"Subiu",IF(AE5<0,"Desceu","Estável")) -> Desceu | AG5: =H5/100 -> 0.1885 | AH5: =C5/(AG5+1) -> 44.5183 | AI5: =(C5-AH5)*N5 -> 5735330905 | AJ5: =IF(AI5>0,"Subiu",IF(AI5<0,"Desceu","Estável")) -> Subiu
A6: CPFE3 | B6: 45317 | C6: 37.1 | D6: 2.03 | E6: 2.49 | F6: -3.66 | G6: -3.66 | H6: 20.7 | I6: 37.32 | J6: 36.37 | K6: 73,42 M | L6: =D6/100 -> 0.0203 | M6: =C6/(L6+1) -> 36.361854 | N6: =VLOOKUP(A6,'Total de Ações'!A:B,2,0) -> 187732538 | O6: =(C6-M6)*N6 -> 1.3857396e+08 | P6: =IF(O6>0,"Subiu",if(O6<0,"Desceu","Estável")) -> Subiu | Q6: =VLOOKUP(A6,Ticker!A:B,2,0) -> CPFL Energia | R6: =VLOOKUP(Q6,ChatGpt!A:C,2,0) -> Energia | S6: =VLOOKUP(Q6,ChatGpt!A:C,3,0) -> 100 | T6: =IF(S6>100,"Mais de 100", IF(S6<50,"Menos de 50","Entre 50 e 100")) -> Entre 50 e 100 | U6: =E6/100 -> 0.0249 | V6: =C6/(U6+1) -> 36.198654 | W6: =(C6-V6)*N6 -> 169212061 | X6: =IF(W6>0,"Subiu",IF(W6<0,"Desceu","Estável")) -> Subiu | Y6: =F6/100 -> -0.0366 | Z6: =C6/(Y6+1) -> 38.509446 | AA6: =(C6-Z6)*N6 -> -2.6459882e+08 | AB6: =IF(AA6>0,"Subiu",(IF(AA6<0,"Desceu","Estável"))) -> Desceu | AC6: =G6/100 -> -0.0366 | AD6: =C6/(AC6+1) -> 38.509446 | AE6: =(C6-AD6)*N6 -> -2.6459882e+08 | AF6: =IF(AE6>0,"Subiu",IF(AE6<0,"Desceu","Estável")) -> Desceu | AG6: =H6/100 -> 0.207 | AH6: =C6/(AG6+1) -> 30.737365 | AI6: =(C6-AH6)*N6 -> 1194473548 | AJ6: =IF(AI6>0,"Subiu",IF(AI6<0,"Desceu","Estável")) -> Subiu
A7: PRIO3 | B7: 45317 | C7: 45.69 | D7: 1.98 | E7: 2.42 | F7: -0.78 | G7: -0.78 | H7: 8.08 | I7: 45.69 | J7: 44.25 | K7: 319,92 M | L7: =D7/100 -> 0.0198 | M7: =C7/(L7+1) -> 44.802903 | N7: =VLOOKUP(A7,'Total de Ações'!A:B,2,0) -> 800010734 | O7: =(C7-M7)*N7 -> 7.096875e+08 | P7: =IF(O7>0,"Subiu",if(O7<0,"Desceu","Estável")) -> Subiu | Q7: =VLOOKUP(A7,Ticker!A:B,2,0) -> PetroRio | R7: =VLOOKUP(Q7,ChatGpt!A:C,2,0) -> Petróleo e Gás | S7: 9 | T7: =IF(S7>100,"Mais de 100", IF(S7<50,"Menos de 50","Entre 50 e 100")) -> Menos de 50 | U7: =E7/100 -> 0.0242 | V7: =C7/(U7+1) -> 44.610428 | W7: =(C7-V7)*N7 -> 8.6366947e+08 | X7: =IF(W7>0,"Subiu",IF(W7<0,"Desceu","Estável")) -> Subiu | Y7: =F7/100 -> -0.0078 | Z7: =C7/(Y7+1) -> 46.049184 | AA7: =(C7-Z7)*N7 -> -2.8735076e+08 | AB7: =IF(AA7>0,"Subiu",(IF(AA7<0,"Desceu","Estável"))) -> Desceu | AC7: =G7/100 -> -0.0078 | AD7: =C7/(AC7+1) -> 46.049184 | AE7: =(C7-AD7)*N7 -> -2.8735076e+08 | AF7: =IF(AE7>0,"Subiu",IF(AE7<0,"Desceu","Estável")) -> Desceu | AG7: =H7/100 -> 0.0808 | AH7: =C7/(AG7+1) -> 42.274241 | AI7: =(C7-AH7)*N7 -> 2732643623 | AJ7: =IF(AI7>0,"Subiu",IF(AI7<0,"Desceu","Estável")) -> Subiu
A8: PETR4 | B8: 45317 | C8: 39.96 | D8: 1.73 | E8: 6.47 | F8: 7.3 | G8: 7.3 | H8: 95.01 | I8: 40.09 | J8: 38.91 | K8: 1,64 B | L8: =D8/100 -> 0.0173 | M8: =C8/(L8+1) -> 39.280448 | N8: =VLOOKUP(A8,'Total de Ações'!A:B,2,0) -> 4566445852 | O8: =(C8-M8)*N8 -> 3103136291 | P8: =IF(O8>0,"Subiu",if(O8<0,"Desceu","Estável")) -> Subiu | Q8: =VLOOKUP(A8,Ticker!A:B,2,0) -> Petrobras | R8: =VLOOKUP(Q8,ChatGpt!A:C,2,0) -> Petróleo e Gás | S8: =VLOOKUP(Q8,ChatGpt!A:C,3,0) -> 60 | T8: =IF(S8>100,"Mais de 100", IF(S8<50,"Menos de 50","Entre 50 e 100")) -> Entre 50 e 100 | U8: =E8/100 -> 0.0647 | V8: =C8/(U8+1) -> 37.531699 | W8: =(C8-V8)*N8 -> 11088704708 | X8: =IF(W8>0,"Subiu",IF(W8<0,"Desceu","Estável")) -> Subiu | Y8: =F8/100 -> 0.073 | Z8: =C8/(Y8+1) -> 37.241379 | AA8: =(C8-Z8)*N8 -> 12414434171 | AB8: =IF(AA8>0,"Subiu",(IF(AA8<0,"Desceu","Estável"))) -> Subiu | AC8: =G8/100 -> 0.073 | AD8: =C8/(AC8+1) -> 37.241379 | AE8: =(C8-AD8)*N8 -> 12414434171 | AF8: =IF(AE8>0,"Subiu",IF(AE8<0,"Desceu","Estável")) -> Subiu | AG8: =H8/100 -> 0.9501 | AH8: =C8/(AG8+1) -> 20.491257 | AI8: =(C8-AH8)*N8 -> 88902961362 | AJ8: =IF(AI8>0,"Subiu",IF(AI8<0,"Desceu","Estável")) -> Subiu
A9: VALE3 | B9: 45317 | C9: 69.5 | D9: 1.66 | E9: 2.06 | F9: -9.97 | G9: -9.97 | H9: -23.49 | I9: 69.81 | J9: 67.5 | K9: 1,89 B | L9: =D9/100 -> 0.0166 | M9: =C9/(L9+1) -> 68.365139 | N9: =VLOOKUP(A9,'Total de Ações'!A:B,2,0) -> 4196924316 | O9: =(C9-M9)*N9 -> 4762926995 | P9: =IF(O9>0,"Subiu",if(O9<0,"Desceu","Estável")) -> Subiu | Q9: =VLOOKUP(A9,Ticker!A:B,2,0) -> Vale | R9: =VLOOKUP(Q9,ChatGpt!A:C,2,0) -> Mineração | S9: =VLOOKUP(Q9,ChatGpt!A:C,3,0) -> 70 | T9: =IF(S9>100,"Mais de 100", IF(S9<50,"Menos de 50","Entre 50 e 100")) -> Entre 50 e 100 | U9: =E9/100 -> 0.0206 | V9: =C9/(U9+1) -> 68.097198 | W9: =(C9-V9)*N9 -> 5887454971 | X9: =IF(W9>0,"Subiu",IF(W9<0,"Desceu","Estável")) -> Subiu | Y9: =F9/100 -> -0.0997 | Z9: =C9/(Y9+1) -> 77.19649 | AA9: =(C9-Z9)*N9 -> -32301586276 | AB9: =IF(AA9>0,"Subiu",(IF(AA9<0,"Desceu","Estável"))) -> Desceu | AC9: =G9/100 -> -0.0997 | AD9: =C9/(AC9+1) -> 77.19649 | AE9: =(C9-AD9)*N9 -> -32301586276 | AF9: =IF(AE9>0,"Subiu",IF(AE9<0,"Desceu","Estável")) -> Desceu | AG9: =H9/100 -> -0.2349 | AH9: =C9/(AG9+1) -> 90.837799 | AI9: =(C9-AH9)*N9 -> -89553127391 | AJ9: =IF(AI9>0,"Subiu",IF(AI9<0,"Desceu","Estável")) -> Desceu
A10: MULT3 | B10: 45317 | C10: 28.19 | D10: 1.58 | E10: 2.03 | F10: -0.81 | G10: -0.81 | H10: 24.02 | I10: 28.36 | J10: 27.71 | K10: 104,16 M | L10: =D10/100 -> 0.0158 | M10: =C10/(L10+1) -> 27.751526 | N10: =VLOOKUP(A10,'Total de Ações'!A:B,2,0) -> 268505432 | O10: =(C10-M10)*N10 -> 1.1773268e+08 | P10: =IF(O10>0,"Subiu",if(O10<0,"Desceu","Estável")) -> Subiu | Q10: =VLOOKUP(A10,Ticker!A:B,2,0) -> Multiplan | R10: =VLOOKUP(Q10,ChatGpt!A:C,2,0) -> Shopping Centers | S10: =VLOOKUP(Q10,ChatGpt!A:C,3,0) -> 50 | T10: =IF(S10>100,"Mais de 100", IF(S10<50,"Menos de 50","Entre 50 e 100")) -> Entre 50 e 100 | U10: =E10/100 -> 0.0203 | V10: =C10/(U10+1) -> 27.629129 | W10: =(C10-V10)*N10 -> 150596994 | X10: =IF(W10>0,"Subiu",IF(W10<0,"Desceu","Estável")) -> Subiu | Y10: =F10/100 -> -0.0081 | Z10: =C10/(Y10+1) -> 28.420204 | AA10: =(C10-Z10)*N10 -> -61810930 | AB10: =IF(AA10>0,"Subiu",(IF(AA10<0,"Desceu","Estável"))) -> Desceu | AC10: =G10/100 -> -0.0081 | AD10: =C10/(AC10+1) -> 28.420204 | AE10: =(C10-AD10)*N10 -> -61810930 | AF10: =IF(AE10>0,"Subiu",IF(AE10<0,"Desceu","Estável")) -> Desceu | AG10: =H10/100 -> 0.2402 | AH10: =C10/(AG10+1) -> 22.730205 | AI10: =(C10-AH10)*N10 -> 1465984667 | AJ10: =IF(AI10>0,"Subiu",IF(AI10<0,"Desceu","Estável")) -> Subiu
A11: ITUB4 | B11: 45317 | C11: 32.81 | D11: 1.48 | E11: -0.39 | F11: -3.36 | G11: -3.36 | H11: 34.25 | I11: 32.91 | J11: 32.35 | K11: 473,2 M | L11: =D11/100 -> 0.0148 | M11: =C11/(L11+1) -> 32.331494 | N11: =VLOOKUP(A11,'Total de Ações'!A:B,2,0) -> 4801593832 | O11: =(C11-M11)*N11 -> 2297591984 | P11: =IF(O11>0,"Subiu",if(O11<0,"Desceu","Estável")) -> Subiu | Q11: =VLOOKUP(A11,Ticker!A:B,2,0) -> Itaú Unibanco | R11: =VLOOKUP(Q11,ChatGpt!A:C,2,0) -> Bancos | S11: =VLOOKUP(Q11,ChatGpt!A:C,3,0) -> 10 | T11: =IF(S11>100,"Mais de 100", IF(S11<50,"Menos de 50","Entre 50 e 100")) -> Menos de 50 | U11: =E11/100 -> -0.0039 | V11: =C11/(U11+1) -> 32.93846 | W11: =(C11-V11)*N11 -> -6.1681271e+08 | X11: =IF(W11>0,"Subiu",IF(W11<0,"Desceu","Estável")) -> Desceu | Y11: =F11/100 -> -0.0336 | Z11: =C11/(Y11+1) -> 33.950745 | AA11: =(C11-Z11)*N11 -> -5477394315 | AB11: =IF(AA11>0,"Subiu",(IF(AA11<0,"Desceu","Estável"))) -> Desceu | AC11: =G11/100 -> -0.0336 | AD11: =C11/(AC11+1) -> 33.950745 | AE11: =(C11-AD11)*N11 -> -5477394315 | AF11: =IF(AE11>0,"Subiu",IF(AE11<0,"Desceu","Estável")) -> Desceu | AG11: =H11/100 -> 0.3425 | AH11: =C11/(AG11+1) -> 24.439479 | AI11: =(C11-AH11)*N11 -> 40191843998 | AJ11: =IF(AI11>0,"Subiu",IF(AI11<0,"Desceu","Estável")) -> Subiu
A12: RDOR3 | B12: 45317 | C12: 27.56 | D12: 1.43 | E12: 3.41 | F12: -4.17 | G12: -4.17 | H12: -6.01 | I12: 27.91 | J12: 26.9 | K12: 71,62 M | L12: =D12/100 -> 0.0143 | M12: =C12/(L12+1) -> 27.171448 | N12: =VLOOKUP(A12,'Total de Ações'!A:B,2,0) -> 1168230366 | O12: =(C12-M12)*N12 -> 453917907 | P12: =IF(O12>0,"Subiu",if(O12<0,"Desceu","Estável")) -> Subiu | Q12: =VLOOKUP(A12,Ticker!A:B,2,0) -> Rede D'Or | R12: =VLOOKUP(Q12,ChatGpt!A:C,2,0) -> Saúde | S12: =VLOOKUP(Q12,ChatGpt!A:C,3,0) -> 40 | T12: =IF(S12>100,"Mais de 100", IF(S12<50,"Menos de 50","Entre 50 e 100")) -> Menos de 50 | U12: =E12/100 -> 0.0341 | V12: =C12/(U12+1) -> 26.651194 | W12: =(C12-V12)*N12 -> 1061694444 | X12: =IF(W12>0,"Subiu",IF(W12<0,"Desceu","Estável")) -> Subiu | Y12: =F12/100 -> -0.0417 | Z12: =C12/(Y12+1) -> 28.759261 | AA12: =(C12-Z12)*N12 -> -1401013341 | AB12: =IF(AA12>0,"Subiu",(IF(AA12<0,"Desceu","Estável"))) -> Desceu | AC12: =G12/100 -> -0.0417 | AD12: =C12/(AC12+1) -> 28.759261 | AE12: =(C12-AD12)*N12 -> -1401013341 | AF12: =IF(AE12>0,"Subiu",IF(AE12<0,"Desceu","Estável")) -> Desceu | AG12: =H12/100 -> -0.0601 | AH12: =C12/(AG12+1) -> 29.322268 | AI12: =(C12-AH12)*N12 -> -2058735372 | AJ12: =IF(AI12>0,"Subiu",IF(AI12<0,"Desceu","Estável")) -> Desceu
A13: BRKM5 | B13: 45317 | C13: 18.55 | D13: 1.42 | E13: 5.1 | F13: -15.14 | G13: -15.14 | H13: -18.39 | I13: 18.73 | J13: 18.29 | K13: 43,31 M | L13: =D13/100 -> 0.0142 | M13: =C13/(L13+1) -> 18.290278 | N13: =VLOOKUP(A13,'Total de Ações'!A:B,2,0) -> 265877867 | O13: =(C13-M13)*N13 -> 69054318 | P13: =IF(O13>0,"Subiu",if(O13<0,"Desceu","Estável")) -> Subiu | Q13: =VLOOKUP(A13,Ticker!A:B,2,0) -> Braskem | R13: =VLOOKUP(Q13,ChatGpt!A:C,2,0) -> Petroquímica | S13: =VLOOKUP(Q13,ChatGpt!A:C,3,0) -> 10 | T13: =IF(S13>100,"Mais de 100", IF(S13<50,"Menos de 50","Entre 50 e 100")) -> Menos de 50 | U13: =E13/100 -> 0.051 | V13: =C13/(U13+1) -> 17.649857 | W13: =(C13-V13)*N13 -> 2.3932803e+08 | X13: =IF(W13>0,"Subiu",IF(W13<0,"Desceu","Estável")) -> Subiu | Y13: =F13/100 -> -0.1514 | Z13: =C13/(Y13+1) -> 21.859533 | AA13: =(C13-Z13)*N13 -> -8.7993167e+08 | AB13: =IF(AA13>0,"Subiu",(IF(AA13<0,"Desceu","Estável"))) -> Desceu | AC13: =G13/100 -> -0.1514 | AD13: =C13/(AC13+1) -> 21.859533 | AE13: =(C13-AD13)*N13 -> -8.7993167e+08 | AF13: =IF(AE13>0,"Subiu",IF(AE13<0,"Desceu","Estável")) -> Desceu | AG13: =H13/100 -> -0.1839 | AH13: =C13/(AG13+1) -> 22.730058 | AI13: =(C13-AH13)*N13 -> -1111384796 | AJ13: =IF(AI13>0,"Subiu",IF(AI13<0,"Desceu","Estável")) -> Desceu
A14: AZUL4 | B14: 45317 | C14: 14.27 | D14: 1.42 | E14: 8.85 | F14: -10.87 | G14: -10.87 | H14: 18.52 | I14: 14.36 | J14: 13.8 | K14: 270,24 M | L14: =D14/100 -> 0.0142 | M14: =C14/(L14+1) -> 14.070203 | N14: =VLOOKUP(A14,'Total de Ações'!A:B,2,0) -> 327593725 | O14: =(C14-M14)*N14 -> 65452206 | P14: =IF(O14>0,"Subiu",if(O14<0,"Desceu","Estável")) -> Subiu | Q14: =VLOOKUP(A14,Ticker!A:B,2,0) -> Azul | R14: =VLOOKUP(Q14,ChatGpt!A:C,2,0) -> Transporte Aéreo | S14: =VLOOKUP(Q14,ChatGpt!A:C,3,0) -> 10 | T14: =IF(S14>100,"Mais de 100", IF(S14<50,"Menos de 50","Entre 50 e 100")) -> Menos de 50 | U14: =E14/100 -> 0.0885 | V14: =C14/(U14+1) -> 13.109784 | W14: =(C14-V14)*N14 -> 3.8007945e+08 | X14: =IF(W14>0,"Subiu",IF(W14<0,"Desceu","Estável")) -> Subiu | Y14: =F14/100 -> -0.1087 | Z14: =C14/(Y14+1) -> 16.010322 | AA14: =(C14-Z14)*N14 -> -5.7011857e+08 | AB14: =IF(AA14>0,"Subiu",(IF(AA14<0,"Desceu","Estável"))) -> Desceu | AC14: =G14/100 -> -0.1087 | AD14: =C14/(AC14+1) -> 16.010322 | AE14: =(C14-AD14)*N14 -> -5.7011857e+08 | AF14: =IF(AE14>0,"Subiu",IF(AE14<0,"Desceu","Estável")) -> Desceu | AG14: =H14/100 -> 0.1852 | AH14: =C14/(AG14+1) -> 12.040162 | AI14: =(C14-AH14)*N14 -> 7.3048094e+08 | AJ14: =IF(AI14>0,"Subiu",IF(AI14<0,"Desceu","Estável")) -> Subiu
A15: RRRP3 | B15: 45317 | C15: 28.75 | D15: 1.41 | E15: -2.71 | F15: 9.4 | G15: 9.4 | H15: -37.7 | I15: 28.75 | J15: 28 | K15: 78,44 M | L15: =D15/100 -> 0.0141 | M15: =C15/(L15+1) -> 28.350261 | N15: =VLOOKUP(A15,'Total de Ações'!A:B,2,0) -> 235665566 | O15: =(C15-M15)*N15 -> 94204643 | P15: =IF(O15>0,"Subiu",if(O15<0,"Desceu","Estável")) -> Subiu | Q15: =VLOOKUP(A15,Ticker!A:B,2,0) -> 3R Petroleum | R15: =VLOOKUP(Q15,ChatGpt!A:C,2,0) -> Petróleo e Gás | S15: 9 | T15: =IF(S15>100,"Mais de 100", IF(S15<50,"Menos de 50","Entre 50 e 100")) -> Menos de 50 | U15: =E15/100 -> -0.0271 | V15: =C15/(U15+1) -> 29.550827 | W15: =(C15-V15)*N15 -> -1.8872745e+08 | X15: =IF(W15>0,"Subiu",IF(W15<0,"Desceu","Estável")) -> Desceu | Y15: =F15/100 -> 0.094 | Z15: =C15/(Y15+1) -> 26.279708 | AA15: =(C15-Z15)*N15 -> 5.8216288e+08 | AB15: =IF(AA15>0,"Subiu",(IF(AA15<0,"Desceu","Estável"))) -> Subiu | AC15: =G15/100 -> 0.094 | AD15: =C15/(AC15+1) -> 26.279708 | AE15: =(C15-AD15)*N15 -> 5.8216288e+08 | AF15: =IF(AE15>0,"Subiu",IF(AE15<0,"Desceu","Estável")) -> Subiu | AG15: =H15/100 -> -0.377 | AH15: =C15/(AG15+1) -> 46.147673 | AI15: =(C15-AH15)*N15 -> -4100032349 | AJ15: =IF(AI15>0,"Subiu",IF(AI15<0,"Desceu","Estável")) -> Desceu
A16: EQTL3 | B16: 45317 | C16: 35.32 | D16: 1.34 | E16: 2.76 | F16: -1.12 | G16: -1.12 | H16: 28.01 | I16: 35.76 | J16: 34.85 | K16: 412,31 M | L16: =D16/100 -> 0.0134 | M16: =C16/(L16+1) -> 34.85297 | N16: =VLOOKUP(A16,'Total de Ações'!A:B,2,0) -> 1095587251 | O16: =(C16-M16)*N16 -> 5.116719e+08 | P16: =IF(O16>0,"Subiu",if(O16<0,"Desceu","Estável")) -> Subiu | Q16: =VLOOKUP(A16,Ticker!A:B,2,0) -> Equatorial Energia | R16: =VLOOKUP(Q16,ChatGpt!A:C,2,0) -> Energia | S16: =VLOOKUP(Q16,ChatGpt!A:C,3,0) -> 20 | T16: =IF(S16>100,"Mais de 100", IF(S16<50,"Menos de 50","Entre 50 e 100")) -> Menos de 50 | U16: =E16/100 -> 0.0276 | V16: =C16/(U16+1) -> 34.371351 | W16: =(C16-V16)*N16 -> 1039328057 | X16: =IF(W16>0,"Subiu",IF(W16<0,"Desceu","Estável")) -> Subiu | Y16: =F16/100 -> -0.0112 | Z16: =C16/(Y16+1) -> 35.720065 | AA16: =(C16-Z16)*N16 -> -4.3830581e+08 | AB16: =IF(AA16>0,"Subiu",(IF(AA16<0,"Desceu","Estável"))) -> Desceu | AC16: =G16/100 -> -0.0112 | AD16: =C16/(AC16+1) -> 35.720065 | AE16: =(C16-AD16)*N16 -> -4.3830581e+08 | AF16: =IF(AE16>0,"Subiu",IF(AE16<0,"Desceu","Estável")) -> Desceu | AG16: =H16/100 -> 0.2801 | AH16: =C16/(AG16+1) -> 27.591594 | AI16: =(C16-AH16)*N16 -> 8467142639 | AJ16: =IF(AI16>0,"Subiu",IF(AI16<0,"Desceu","Estável")) -> Subiu
A17: CSNA3 | B17: 45317 | C17: 18.16 | D17: 1.33 | E17: 4.79 | F17: -7.63 | G17: -7.63 | H17: 12.45 | I17: 18.49 | J17: 18 | K17: 109,86 M | L17: =D17/100 -> 0.0133 | M17: =C17/(L17+1) -> 17.921642 | N17: =VLOOKUP(A17,'Total de Ações'!A:B,2,0) -> 600865451 | O17: =(C17-M17)*N17 -> 1.4322099e+08 | P17: =IF(O17>0,"Subiu",if(O17<0,"Desceu","Estável")) -> Subiu | Q17: =VLOOKUP(A17,Ticker!A:B,2,0) -> Siderúrgica Nacional | R17: =VLOOKUP(Q17,ChatGpt!A:C,2,0) -> Siderurgia | S17: =VLOOKUP(Q17,ChatGpt!A:C,3,0) -> 70 | T17: =IF(S17>100,"Mais de 100", IF(S17<50,"Menos de 50","Entre 50 e 100")) -> Entre 50 e 100 | U17: =E17/100 -> 0.0479 | V17: =C17/(U17+1) -> 17.329898 | W17: =(C17-V17)*N17 -> 4.9877968e+08 | X17: =IF(W17>0,"Subiu",IF(W17<0,"Desceu","Estável")) -> Subiu | Y17: =F17/100 -> -0.0763 | Z17: =C17/(Y17+1) -> 19.660063 | AA17: =(C17-Z17)*N17 -> -9.0133591e+08 | AB17: =IF(AA17>0,"Subiu",(IF(AA17<0,"Desceu","Estável"))) -> Desceu | AC17: =G17/100 -> -0.0763 | AD17: =C17/(AC17+1) -> 19.660063 | AE17: =(C17-AD17)*N17 -> -9.0133591e+08 | AF17: =IF(AE17>0,"Subiu",IF(AE17<0,"Desceu","Estável")) -> Desceu | AG17: =H17/100 -> 0.1245 | AH17: =C17/(AG17+1) -> 16.1494 | AI17: =(C17-AH17)*N17 -> 1208100236 | AJ17: =IF(AI17>0,"Subiu",IF(AI17<0,"Desceu","Estável")) -> Subiu
A18: YDUQ3 | B18: 45317 | C18: 19.77 | D18: 1.28 | E18: -5.9 | F18: -11.82 | G18: -11.82 | H18: 108.45 | I18: 19.78 | J18: 18.99 | K18: 63,48 M | L18: =D18/100 -> 0.0128 | M18: =C18/(L18+1) -> 19.520142 | N18: =VLOOKUP(A18,'Total de Ações'!A:B,2,0) -> 289347914 | O18: =(C18-M18)*N18 -> 72295839 | P18: =IF(O18>0,"Subiu",if(O18<0,"Desceu","Estável")) -> Subiu | Q18: =VLOOKUP(A18,Ticker!A:B,2,0) -> YDUQS | R18: =VLOOKUP(Q18,ChatGpt!A:C,2,0) -> Educação | S18: =VLOOKUP(Q18,ChatGpt!A:C,3,0) -> 50 | T18: =IF(S18>100,"Mais de 100", IF(S18<50,"Menos de 50","Entre 50 e 100")) -> Entre 50 e 100 | U18: =E18/100 -> -0.059 | V18: =C18/(U18+1) -> 21.009564 | W18: =(C18-V18)*N18 -> -3.5866534e+08 | X18: =IF(W18>0,"Subiu",IF(W18<0,"Desceu","Estável")) -> Desceu | Y18: =F18/100 -> -0.1182 | Z18: =C18/(Y18+1) -> 22.42005 | AA18: =(C18-Z18)*N18 -> -766786410 | AB18: =IF(AA18>0,"Subiu",(IF(AA18<0,"Desceu","Estável"))) -> Desceu | AC18: =G18/100 -> -0.1182 | AD18: =C18/(AC18+1) -> 22.42005 | AE18: =(C18-AD18)*N18 -> -766786410 | AF18: =IF(AE18>0,"Subiu",IF(AE18<0,"Desceu","Estável")) -> Desceu | AG18: =H18/100 -> 1.0845 | AH18: =C18/(AG18+1) -> 9.4842888 | AI18: =(C18-AH18)*N18 -> 2976149080 | AJ18: =IF(AI18>0,"Subiu",IF(AI18<0,"Desceu","Estável")) -> Subiu
A19: UGPA3 | B19: 45317 | C19: 28.31 | D19: 1.28 | E19: 2.35 | F19: 6.79 | G19: 6.79 | H19: 119.82 | I19: 28.39 | J19: 27.84 | K19: 104,52 M | L19: =D19/100 -> 0.0128 | M19: =C19/(L19+1) -> 27.952212 | N19: =VLOOKUP(A19,'Total de Ações'!A:B,2,0) -> 1086411192 | O19: =(C19-M19)*N19 -> 388705224 | P19: =IF(O19>0,"Subiu",if(O19<0,"Desceu","Estável")) -> Subiu | Q19: =VLOOKUP(A19,Ticker!A:B,2,0) -> Ultrapar | R19: =VLOOKUP(Q19,ChatGpt!A:C,2,0) -> Distribuição | S19: =VLOOKUP(Q19,ChatGpt!A:C,3,0) -> 80 | T19: =IF(S19>100,"Mais de 100", IF(S19<50,"Menos de 50","Entre 50 e 100")) -> Entre 50 e 100 | U19: =E19/100 -> 0.0235 | V19: =C19/(U19+1) -> 27.65999 | W19: =(C19-V19)*N19 -> 7.0617789e+08 | X19: =IF(W19>0,"Subiu",IF(W19<0,"Desceu","Estável")) -> Subiu | Y19: =F19/100 -> 0.0679 | Z19: =C19/(Y19+1) -> 26.509973 | AA19: =(C19-Z19)*N19 -> 1955569648 | AB19: =IF(AA19>0,"Subiu",(IF(AA19<0,"Desceu","Estável"))) -> Subiu | AC19: =G19/100 -> 0.0679 | AD19: =C19/(AC19+1) -> 26.509973 | AE19: =(C19-AD19)*N19 -> 1955569648 | AF19: =IF(AE19>0,"Subiu",IF(AE19<0,"Desceu","Estável")) -> Subiu | AG19: =H19/100 -> 1.1982 | AH19: =C19/(AG19+1) -> 12.878719 | AI19: =(C19-AH19)*N19 -> 16764716438 | AJ19: =IF(AI19>0,"Subiu",IF(AI19<0,"Desceu","Estável")) -> Subiu
A20: MRVE3 | B20: 45317 | C20: 8.08 | D20: 1.25 | E20: 1.38 | F20: -28.05 | G20: -28.05 | H20: 14.12 | I20: 8.23 | J20: 7.93 | K20: 109,48 M | L20: =D20/100 -> 0.0125 | M20: =C20/(L20+1) -> 7.9802469 | N20: =VLOOKUP(A20,'Total de Ações'!A:B,2,0) -> 376187582 | O20: =(C20-M20)*N20 -> 37525872 | P20: =IF(O20>0,"Subiu",if(O20<0,"Desceu","Estável")) -> Subiu | Q20: =VLOOKUP(A20,Ticker!A:B,2,0) -> MRV | R20: =VLOOKUP(Q20,ChatGpt!A:C,2,0) -> Construção Civil | S20: =VLOOKUP(Q20,ChatGpt!A:C,3,0) -> 40 | T20: =IF(S20>100,"Mais de 100", IF(S20<50,"Menos de 50","Entre 50 e 100")) -> Menos de 50 | U20: =E20/100 -> 0.0138 | V20: =C20/(U20+1) -> 7.9700138 | W20: =(C20-V20)*N20 -> 41375439 | X20: =IF(W20>0,"Subiu",IF(W20<0,"Desceu","Estável")) -> Subiu | Y20: =F20/100 -> -0.2805 | Z20: =C20/(Y20+1) -> 11.230021 | AA20: =(C20-Z20)*N20 -> -1184998726 | AB20: =IF(AA20>0,"Subiu",(IF(AA20<0,"Desceu","Estável"))) -> Desceu | AC20: =G20/100 -> -0.2805 | AD20: =C20/(AC20+1) -> 11.230021 | AE20: =(C20-AD20)*N20 -> -1184998726 | AF20: =IF(AE20>0,"Subiu",IF(AE20<0,"Desceu","Estável")) -> Desceu | AG20: =H20/100 -> 0.1412 | AH20: =C20/(AG20+1) -> 7.0802664 | AI20: =(C20-AH20)*N20 -> 3.7608737e+08 | AJ20: =IF(AI20>0,"Subiu",IF(AI20<0,"Desceu","Estável")) -> Subiu
A21: ARZZ3 | B21: 45317 | C21: 57.91 | D21: 1.15 | E21: -1.03 | F21: -10.26 | G21: -10.26 | H21: -28.97 | I21: 59.29 | J21: 56.22 | K21: 202,83 M | L21: =D21/100 -> 0.0115 | M21: =C21/(L21+1) -> 57.251607 | N21: =VLOOKUP(A21,'Total de Ações'!A:B,2,0) -> 62305891 | O21: =(C21-M21)*N21 -> 41021792 | P21: =IF(O21>0,"Subiu",if(O21<0,"Desceu","Estável")) -> Subiu | Q21: =VLOOKUP(A21,Ticker!A:B,2,0) -> Arezzo | R21: =VLOOKUP(Q21,ChatGpt!A:C,2,0) -> Moda | S21: =VLOOKUP(Q21,ChatGpt!A:C,3,0) -> 40 | T21: =IF(S21>100,"Mais de 100", IF(S21<50,"Menos de 50","Entre 50 e 100")) -> Menos de 50 | U21: =E21/100 -> -0.0103 | V21: =C21/(U21+1) -> 58.512681 | W21: =(C21-V21)*N21 -> -37550552 | X21: =IF(W21>0,"Subiu",IF(W21<0,"Desceu","Estável")) -> Desceu | Y21: =F21/100 -> -0.1026 | Z21: =C21/(Y21+1) -> 64.530867 | AA21: =(C21-Z21)*N21 -> -4.1251901e+08 | AB21: =IF(AA21>0,"Subiu",(IF(AA21<0,"Desceu","Estável"))) -> Desceu | AC21: =G21/100 -> -0.1026 | AD21: =C21/(AC21+1) -> 64.530867 | AE21: =(C21-AD21)*N21 -> -4.1251901e+08 | AF21: =IF(AE21>0,"Subiu",IF(AE21<0,"Desceu","Estável")) -> Desceu | AG21: =H21/100 -> -0.2897 | AH21: =C21/(AG21+1) -> 81.528931 | AI21: =(C21-AH21)*N21 -> -1471598568 | AJ21: =IF(AI21>0,"Subiu",IF(AI21<0,"Desceu","Estável")) -> Desceu
A22: BBDC4 | B22: 45317 | C22: 15.52 | D22: 1.04 | E22: -0.77 | F22: -9.08 | G22: -9.08 | H22: 16.11 | I22: 15.62 | J22: 15.35 | K22: 354,3 M | L22: =D22/100 -> 0.0104 | M22: =C22/(L22+1) -> 15.360253 | N22: =VLOOKUP(A22,'Total de Ações'!A:B,2,0) -> 5146576868 | O22: =(C22-M22)*N22 -> 8.2214834e+08 | P22: =IF(O22>0,"Subiu",if(O22<0,"Desceu","Estável")) -> Subiu | Q22: =VLOOKUP(A22,Ticker!A:B,2,0) -> Banco Bradesco | R22: =VLOOKUP(Q22,ChatGpt!A:C,2,0) -> Bancos | S22: =VLOOKUP(Q22,ChatGpt!A:C,3,0) -> 70 | T22: =IF(S22>100,"Mais de 100", IF(S22<50,"Menos de 50","Entre 50 e 100")) -> Entre 50 e 100 | U22: =E22/100 -> -0.0077 | V22: =C22/(U22+1) -> 15.640431 | W22: =(C22-V22)*N22 -> -6.1980905e+08 | X22: =IF(W22>0,"Subiu",IF(W22<0,"Desceu","Estável")) -> Desceu | Y22: =F22/100 -> -0.0908 | Z22: =C22/(Y22+1) -> 17.069952 | AA22: =(C22-Z22)*N22 -> -7976945081 | AB22: =IF(AA22>0,"Subiu",(IF(AA22<0,"Desceu","Estável"))) -> Desceu | AC22: =G22/100 -> -0.0908 | AD22: =C22/(AC22+1) -> 17.069952 | AE22: =(C22-AD22)*N22 -> -7976945081 | AF22: =IF(AE22>0,"Subiu",IF(AE22<0,"Desceu","Estável")) -> Desceu | AG22: =H22/100 -> 0.1611 | AH22: =C22/(AG22+1) -> 13.366635 | AI22: =(C22-AH22)*N22 -> 11082458047 | AJ22: =IF(AI22>0,"Subiu",IF(AI22<0,"Desceu","Estável")) -> Subiu
A23: BEEF3 | B23: 45317 | C23: 7.19 | D23: 0.98 | E23: 6.05 | F23: -3.75 | G23: -3.75 | H23: -48.31 | I23: 7.24 | J23: 7.11 | K23: 42,44 M | L23: =D23/100 -> 0.0098 | M23: =C23/(L23+1) -> 7.1202218 | N23: =VLOOKUP(A23,'Total de Ações'!A:B,2,0) -> 261036182 | O23: =(C23-M23)*N23 -> 18214628 | P23: =IF(O23>0,"Subiu",if(O23<0,"Desceu","Estável")) -> Subiu | Q23: =VLOOKUP(A23,Ticker!A:B,2,0) -> Minerva | R23: =VLOOKUP(Q23,ChatGpt!A:C,2,0) -> Alimentos | S23: =VLOOKUP(Q23,ChatGpt!A:C,3,0) -> 90 | T23: =IF(S23>100,"Mais de 100", IF(S23<50,"Menos de 50","Entre 50 e 100")) -> Entre 50 e 100 | U23: =E23/100 -> 0.0605 | V23: =C23/(U23+1) -> 6.7798208 | W23: =(C23-V23)*N23 -> 1.070716e+08 | X23: =IF(W23>0,"Subiu",IF(W23<0,"Desceu","Estável")) -> Subiu | Y23: =F23/100 -> -0.0375 | Z23: =C23/(Y23+1) -> 7.4701299 | AA23: =(C23-Z23)*N23 -> -73124032 | AB23: =IF(AA23>0,"Subiu",(IF(AA23<0,"Desceu","Estável"))) -> Desceu | AC23: =G23/100 -> -0.0375 | AD23: =C23/(AC23+1) -> 7.4701299 | AE23: =(C23-AD23)*N23 -> -73124032 | AF23: =IF(AE23>0,"Subiu",IF(AE23<0,"Desceu","Estável")) -> Desceu | AG23: =H23/100 -> -0.4831 | AH23: =C23/(AG23+1) -> 13.909847 | AI23: =(C23-AH23)*N23 -> -1754123248 | AJ23: =IF(AI23>0,"Subiu",IF(AI23<0,"Desceu","Estável")) -> Desceu
A24: PCAR3 | B24: 45317 | C24: 4.14 | D24: 0.97 | E24: -6.33 | F24: 1.97 | G24: 1.97 | H24: -51.18 | I24: 4.2 | J24: 4.08 | K24: 21,18 M | L24: =D24/100 -> 0.0097 | M24: =C24/(L24+1) -> 4.1002278 | N24: =VLOOKUP(A24,'Total de Ações'!A:B,2,0) -> 159430826 | O24: =(C24-M24)*N24 -> 6340916.2 | P24: =IF(O24>0,"Subiu",if(O24<0,"Desceu","Estável")) -> Subiu | Q24: =VLOOKUP(A24,Ticker!A:B,2,0) -> Grupo Pão de Açúcar | R24: =VLOOKUP(Q24,ChatGpt!A:C,2,0) -> Alimentos | S24: =VLOOKUP(Q24,ChatGpt!A:C,3,0) -> 70 | T24: =IF(S24>100,"Mais de 100", IF(S24<50,"Menos de 50","Entre 50 e 100")) -> Entre 50 e 100 | U24: =E24/100 -> -0.0633 | V24: =C24/(U24+1) -> 4.4197715 | W24: =(C24-V24)*N24 -> -44604207 | X24: =IF(W24>0,"Subiu",IF(W24<0,"Desceu","Estável")) -> Desceu | Y24: =F24/100 -> 0.0197 | Z24: =C24/(Y24+1) -> 4.0600177 | AA24: =(C24-Z24)*N24 -> 12751652 | AB24: =IF(AA24>0,"Subiu",(IF(AA24<0,"Desceu","Estável"))) -> Subiu | AC24: =G24/100 -> 0.0197 | AD24: =C24/(AC24+1) -> 4.0600177 | AE24: =(C24-AD24)*N24 -> 12751652 | AF24: =IF(AE24>0,"Subiu",IF(AE24<0,"Desceu","Estável")) -> Subiu | AG24: =H24/100 -> -0.5118 | AH24: =C24/(AG24+1) -> 8.4801311 | AI24: =(C24-AH24)*N24 -> -6.9195069e+08 | AJ24: =IF(AI24>0,"Subiu",IF(AI24<0,"Desceu","Estável")) -> Desceu
A25: BRFS3 | B25: 45317 | C25: 14.61 | D25: 0.96 | E25: 12.38 | F25: 5.79 | G25: 5.79 | H25: 78.17 | I25: 14.93 | J25: 14.46 | K25: 101,38 M | L25: =D25/100 -> 0.0096 | M25: =C25/(L25+1) -> 14.471078 | N25: =VLOOKUP(A25,'Total de Ações'!A:B,2,0) -> 1677525446 | O25: =(C25-M25)*N25 -> 2.3304577e+08 | P25: =IF(O25>0,"Subiu",if(O25<0,"Desceu","Estável")) -> Subiu | Q25: =VLOOKUP(A25,Ticker!A:B,2,0) -> BRF | R25: =VLOOKUP(Q25,ChatGpt!A:C,2,0) -> Alimentos | S25: =VLOOKUP(Q25,ChatGpt!A:C,3,0) -> 80 | T25: =IF(S25>100,"Mais de 100", IF(S25<50,"Menos de 50","Entre 50 e 100")) -> Entre 50 e 100 | U25: =E25/100 -> 0.1238 | V25: =C25/(U25+1) -> 13.000534 | W25: =(C25-V25)*N25 -> 2699920332 | X25: =IF(W25>0,"Subiu",IF(W25<0,"Desceu","Estável")) -> Subiu | Y25: =F25/100 -> 0.0579 | Z25: =C25/(Y25+1) -> 13.810379 | AA25: =(C25-Z25)*N25 -> 1341384486 | AB25: =IF(AA25>0,"Subiu",(IF(AA25<0,"Desceu","Estável"))) -> Subiu | AC25: =G25/100 -> 0.0579 | AD25: =C25/(AC25+1) -> 13.810379 | AE25: =(C25-AD25)*N25 -> 1341384486 | AF25: =IF(AE25>0,"Subiu",IF(AE25<0,"Desceu","Estável")) -> Subiu | AG25: =H25/100 -> 0.7817 | AH25: =C25/(AG25+1) -> 8.2000337 | AI25: =(C25-AH25)*N25 -> 10752881617 | AJ25: =IF(AI25>0,"Subiu",IF(AI25<0,"Desceu","Estável")) -> Subiu
A26: VIVT3 | B26: 45317 | C26: 51.2 | D26: 0.88 | E26: 1.09 | F26: -4.19 | G26: -4.19 | H26: 32.78 | I26: 51.26 | J26: 50.62 | K26: 64,92 M | L26: =D26/100 -> 0.0088 | M26: =C26/(L26+1) -> 50.75337 | N26: =VLOOKUP(A26,'Total de Ações'!A:B,2,0) -> 423091712 | O26: =(C26-M26)*N26 -> 1.8896531e+08 | P26: =IF(O26>0,"Subiu",if(O26<0,"Desceu","Estável")) -> Subiu | Q26: =VLOOKUP(A26,Ticker!A:B,2,0) -> Vivo | R26: =VLOOKUP(Q26,ChatGpt!A:C,2,0) -> Telecomunicações | S26: =VLOOKUP(Q26,ChatGpt!A:C,3,0) -> 20 | T26: =IF(S26>100,"Mais de 100", IF(S26<50,"Menos de 50","Entre 50 e 100")) -> Menos de 50 | U26: =E26/100 -> 0.0109 | V26: =C26/(U26+1) -> 50.647937 | W26: =(C26-V26)*N26 -> 2.3357308e+08 | X26: =IF(W26>0,"Subiu",IF(W26<0,"Desceu","Estável")) -> Subiu | Y26: =F26/100 -> -0.0419 | Z26: =C26/(Y26+1) -> 53.439098 | AA26: =(C26-Z26)*N26 -> -9.473439e+08 | AB26: =IF(AA26>0,"Subiu",(IF(AA26<0,"Desceu","Estável"))) -> Desceu | AC26: =G26/100 -> -0.0419 | AD26: =C26/(AC26+1) -> 53.439098 | AE26: =(C26-AD26)*N26 -> -9.473439e+08 | AF26: =IF(AE26>0,"Subiu",IF(AE26<0,"Desceu","Estável")) -> Desceu | AG26: =H26/100 -> 0.3278 | AH26: =C26/(AG26+1) -> 38.560024 | AI26: =(C26-AH26)*N26 -> 5347869043 | AJ26: =IF(AI26>0,"Subiu",IF(AI26<0,"Desceu","Estável")) -> Subiu
A27: RAIL3 | B27: 45317 | C27: 22.64 | D27: 0.84 | E27: 1.07 | F27: -1.35 | G27: -1.35 | H27: 20.93 | I27: 22.83 | J27: 22.32 | K27: 178,44 M | L27: =D27/100 -> 0.0084 | M27: =C27/(L27+1) -> 22.451408 | N27: =VLOOKUP(A27,'Total de Ações'!A:B,2,0) -> 1218352541 | O27: =(C27-M27)*N27 -> 2.2977133e+08 | P27: =IF(O27>0,"Subiu",if(O27<0,"Desceu","Estável")) -> Subiu | Q27: =VLOOKUP(A27,Ticker!A:B,2,0) -> Rumo | R27: =VLOOKUP(Q27,ChatGpt!A:C,2,0) -> Logística | S27: =VLOOKUP(Q27,ChatGpt!A:C,3,0) -> 10 | T27: =IF(S27>100,"Mais de 100", IF(S27<50,"Menos de 50","Entre 50 e 100")) -> Menos de 50 | U27: =E27/100 -> 0.0107 | V27: =C27/(U27+1) -> 22.400317 | W27: =(C27-V27)*N27 -> 2.9201886e+08 | X27: =IF(W27>0,"Subiu",IF(W27<0,"Desceu","Estável")) -> Subiu | Y27: =F27/100 -> -0.0135 | Z27: =C27/(Y27+1) -> 22.949823 | AA27: =(C27-Z27)*N27 -> -3.7747316e+08 | AB27: =IF(AA27>0,"Subiu",(IF(AA27<0,"Desceu","Estável"))) -> Desceu | AC27: =G27/100 -> -0.0135 | AD27: =C27/(AC27+1) -> 22.949823 | AE27: =(C27-AD27)*N27 -> -3.7747316e+08 | AF27: =IF(AE27>0,"Subiu",IF(AE27<0,"Desceu","Estável")) -> Desceu | AG27: =H27/100 -> 0.2093 | AH27: =C27/(AG27+1) -> 18.721574 | AI27: =(C27-AH27)*N27 -> 4774023708 | AJ27: =IF(AI27>0,"Subiu",IF(AI27<0,"Desceu","Estável")) -> Subiu
... A63: ELET3 | B63: 45317 | C63: 40.86 | D63: -0.65 | E63: -2.04 | F63: -3.7 | G63: -3.7 | H63: -3.64 | I63: 41.44 | J63: 40.86 | K63: 109,87 M | L63: =D63/100 -> -0.0065 | M63: =C63/(L63+1) -> 41.127328 | N63: =VLOOKUP(A63,'Total de Ações'!A:B,2,0) -> 1980568384 | O63: =(C63-M63)*N63 -> -5.2946065e+08 | P63: =IF(O63>0,"Subiu",if(O63<0,"Desceu","Estável")) -> Desceu | Q63: =VLOOKUP(A63,Ticker!A:B,2,0) -> Eletrobras | R63: =VLOOKUP(Q63,ChatGpt!A:C,2,0) -> Energia | S63: =VLOOKUP(Q63,ChatGpt!A:C,3,0) -> 50 | T63: =IF(S63>100,"Mais de 100", IF(S63<50,"Menos de 50","Entre 50 e 100")) -> Entre 50 e 100 | U63: =E63/100 -> -0.0204 | V63: =C63/(U63+1) -> 41.710902 | W63: =(C63-V63)*N63 -> -1685270409 | X63: =IF(W63>0,"Subiu",IF(W63<0,"Desceu","Estável")) -> Desceu | Y63: =F63/100 -> -0.037 | Z63: =C63/(Y63+1) -> 42.429907 | AA63: =(C63-Z63)*N63 -> -3109307263 | AB63: =IF(AA63>0,"Subiu",(IF(AA63<0,"Desceu","Estável"))) -> Desceu | AC63: =G63/100 -> -0.037 | AD63: =C63/(AC63+1) -> 42.429907 | AE63: =(C63-AD63)*N63 -> -3109307263 | AF63: =IF(AE63>0,"Subiu",IF(AE63<0,"Desceu","Estável")) -> Desceu | AG63: =H63/100 -> -0.0364 | AH63: =C63/(AG63+1) -> 42.403487 | AI63: =(C63-AH63)*N63 -> -3056981403 | AJ63: =IF(AI63>0,"Subiu",IF(AI63<0,"Desceu","Estável")) -> Desceu
A64: PETZ3 | B64: 45317 | C64: 3.4 | D64: -0.87 | E64: -4.23 | F64: -13.92 | G64: -13.92 | H64: -46.63 | I64: 3.47 | J64: 3.35 | K64: 49,03 M | L64: =D64/100 -> -0.0087 | M64: =C64/(L64+1) -> 3.4298396 | N64: =VLOOKUP(A64,'Total de Ações'!A:B,2,0) -> 309729428 | O64: =(C64-M64)*N64 -> -9242203.7 | P64: =IF(O64>0,"Subiu",if(O64<0,"Desceu","Estável")) -> Desceu | Q64: =VLOOKUP(A64,Ticker!A:B,2,0) -> Petz | R64: =VLOOKUP(Q64,ChatGpt!A:C,2,0) -> Varejo | S64: 9 | T64: =IF(S64>100,"Mais de 100", IF(S64<50,"Menos de 50","Entre 50 e 100")) -> Menos de 50 | U64: =E64/100 -> -0.0423 | V64: =C64/(U64+1) -> 3.5501723 | W64: =(C64-V64)*N64 -> -46512777 | X64: =IF(W64>0,"Subiu",IF(W64<0,"Desceu","Estável")) -> Desceu | Y64: =F64/100 -> -0.1392 | Z64: =C64/(Y64+1) -> 3.9498141 | AA64: =(C64-Z64)*N64 -> -1.7029361e+08 | AB64: =IF(AA64>0,"Subiu",(IF(AA64<0,"Desceu","Estável"))) -> Desceu | AC64: =G64/100 -> -0.1392 | AD64: =C64/(AC64+1) -> 3.9498141 | AE64: =(C64-AD64)*N64 -> -1.7029361e+08 | AF64: =IF(AE64>0,"Subiu",IF(AE64<0,"Desceu","Estável")) -> Desceu | AG64: =H64/100 -> -0.4663 | AH64: =C64/(AG64+1) -> 6.3706202 | AI64: =(C64-AH64)*N64 -> -9.2008849e+08 | AJ64: =IF(AI64>0,"Subiu",IF(AI64<0,"Desceu","Estável")) -> Desceu
A65: EZTC3 | B65: 45317 | C65: 15.91 | D65: -0.93 | E65: -2.39 | F65: -14.92 | G65: -14.92 | H65: 8.93 | I65: 16.31 | J65: 15.85 | K65: 22,15 M | L65: =D65/100 -> -0.0093 | M65: =C65/(L65+1) -> 16.059352 | N65: =VLOOKUP(A65,'Total de Ações'!A:B,2,0) -> 91514307 | O65: =(C65-M65)*N65 -> -13667842 | P65: =IF(O65>0,"Subiu",if(O65<0,"Desceu","Estável")) -> Desceu | Q65: =VLOOKUP(A65,Ticker!A:B,2,0) -> EZTEC | R65: =VLOOKUP(Q65,ChatGpt!A:C,2,0) -> Construção Civil | S65: =VLOOKUP(Q65,ChatGpt!A:C,3,0) -> 40 | T65: =IF(S65>100,"Mais de 100", IF(S65<50,"Menos de 50","Entre 50 e 100")) -> Menos de 50 | U65: =E65/100 -> -0.0239 | V65: =C65/(U65+1) -> 16.299559 | W65: =(C65-V65)*N65 -> -35650265 | X65: =IF(W65>0,"Subiu",IF(W65<0,"Desceu","Estável")) -> Desceu | Y65: =F65/100 -> -0.1492 | Z65: =C65/(Y65+1) -> 18.700047 | AA65: =(C65-Z65)*N65 -> -255329219 | AB65: =IF(AA65>0,"Subiu",(IF(AA65<0,"Desceu","Estável"))) -> Desceu | AC65: =G65/100 -> -0.1492 | AD65: =C65/(AC65+1) -> 18.700047 | AE65: =(C65-AD65)*N65 -> -255329219 | AF65: =IF(AE65>0,"Subiu",IF(AE65<0,"Desceu","Estável")) -> Desceu | AG65: =H65/100 -> 0.0893 | AH65: =C65/(AG65+1) -> 14.60571 | AI65: =(C65-AH65)*N65 -> 1.1936119e+08 | AJ65: =IF(AI65>0,"Subiu",IF(AI65<0,"Desceu","Estável")) -> Subiu
A66: FLRY3 | B66: 45317 | C66: 16.49 | D66: -1.07 | E66: 1.04 | F66: -8.59 | G66: -8.59 | H66: 17.16 | I66: 16.71 | J66: 16.4 | K66: 37,01 M | L66: =D66/100 -> -0.0107 | M66: =C66/(L66+1) -> 16.668351 | N66: =VLOOKUP(A66,'Total de Ações'!A:B,2,0) -> 240822651 | O66: =(C66-M66)*N66 -> -42951047 | P66: =IF(O66>0,"Subiu",if(O66<0,"Desceu","Estável")) -> Desceu | Q66: =VLOOKUP(A66,Ticker!A:B,2,0) -> Fleury | R66: =VLOOKUP(Q66,ChatGpt!A:C,2,0) -> Saúde | S66: =VLOOKUP(Q66,ChatGpt!A:C,3,0) -> 50 | T66: =IF(S66>100,"Mais de 100", IF(S66<50,"Menos de 50","Entre 50 e 100")) -> Entre 50 e 100 | U66: =E66/100 -> 0.0104 | V66: =C66/(U66+1) -> 16.320269 | W66: =(C66-V66)*N66 -> 40875021 | X66: =IF(W66>0,"Subiu",IF(W66<0,"Desceu","Estável")) -> Subiu | Y66: =F66/100 -> -0.0859 | Z66: =C66/(Y66+1) -> 18.039602 | AA66: =(C66-Z66)*N66 -> -3.7317921e+08 | AB66: =IF(AA66>0,"Subiu",(IF(AA66<0,"Desceu","Estável"))) -> Desceu | AC66: =G66/100 -> -0.0859 | AD66: =C66/(AC66+1) -> 18.039602 | AE66: =(C66-AD66)*N66 -> -3.7317921e+08 | AF66: =IF(AE66>0,"Subiu",IF(AE66<0,"Desceu","Estável")) -> Desceu | AG66: =H66/100 -> 0.1716 | AH66: =C66/(AG66+1) -> 14.07477 | AI66: =(C66-AH66)*N66 -> 5.816422e+08 | AJ66: =IF(AI66>0,"Subiu",IF(AI66<0,"Desceu","Estável")) -> Subiu
A67: SOMA3 | B67: 45317 | C67: 6.95 | D67: -1.27 | E67: -0.43 | F67: -6.71 | G67: -6.71 | H67: -30.01 | I67: 7.14 | J67: 6.87 | K67: 60,82 M | L67: =D67/100 -> -0.0127 | M67: =C67/(L67+1) -> 7.0394004 | N67: =VLOOKUP(A67,'Total de Ações'!A:B,2,0) -> 496029967 | O67: =(C67-M67)*N67 -> -44345270 | P67: =IF(O67>0,"Subiu",if(O67<0,"Desceu","Estável")) -> Desceu | Q67: =VLOOKUP(A67,Ticker!A:B,2,0) -> Grupo Soma | R67: =VLOOKUP(Q67,ChatGpt!A:C,2,0) -> Varejo | S67: =VLOOKUP(Q67,ChatGpt!A:C,3,0) -> 20 | T67: =IF(S67>100,"Mais de 100", IF(S67<50,"Menos de 50","Entre 50 e 100")) -> Menos de 50 | U67: =E67/100 -> -0.0043 | V67: =C67/(U67+1) -> 6.9800141 | W67: =(C67-V67)*N67 -> -14887873 | X67: =IF(W67>0,"Subiu",IF(W67<0,"Desceu","Estável")) -> Desceu | Y67: =F67/100 -> -0.0671 | Z67: =C67/(Y67+1) -> 7.4498874 | AA67: =(C67-Z67)*N67 -> -2.4795915e+08 | AB67: =IF(AA67>0,"Subiu",(IF(AA67<0,"Desceu","Estável"))) -> Desceu | AC67: =G67/100 -> -0.0671 | AD67: =C67/(AC67+1) -> 7.4498874 | AE67: =(C67-AD67)*N67 -> -2.4795915e+08 | AF67: =IF(AE67>0,"Subiu",IF(AE67<0,"Desceu","Estável")) -> Desceu | AG67: =H67/100 -> -0.3001 | AH67: =C67/(AG67+1) -> 9.92999 | AI67: =(C67-AH67)*N67 -> -1478164341 | AJ67: =IF(AI67>0,"Subiu",IF(AI67<0,"Desceu","Estável")) -> Desceu
A68: ALPA4 | B68: 45317 | C68: 8.67 | D68: -1.36 | E68: 4.08 | F68: -14.33 | G68: -14.33 | H68: -34.52 | I68: 8.8 | J68: 8.62 | K68: 14 M | L68: =D68/100 -> -0.0136 | M68: =C68/(L68+1) -> 8.7895377 | N68: =VLOOKUP(A68,'Total de Ações'!A:B,2,0) -> 176733968 | O68: =(C68-M68)*N68 -> -21126374 | P68: =IF(O68>0,"Subiu",if(O68<0,"Desceu","Estável")) -> Desceu | Q68: =VLOOKUP(A68,Ticker!A:B,2,0) -> Alpargatas | R68: =VLOOKUP(Q68,ChatGpt!A:C,2,0) -> Calçados | S68: =VLOOKUP(Q68,ChatGpt!A:C,3,0) -> 100 | T68: =IF(S68>100,"Mais de 100", IF(S68<50,"Menos de 50","Entre 50 e 100")) -> Entre 50 e 100 | U68: =E68/100 -> 0.0408 | V68: =C68/(U68+1) -> 8.3301307 | W68: =(C68-V68)*N68 -> 60066456 | X68: =IF(W68>0,"Subiu",IF(W68<0,"Desceu","Estável")) -> Subiu | Y68: =F68/100 -> -0.1433 | Z68: =C68/(Y68+1) -> 10.120229 | AA68: =(C68-Z68)*N68 -> -2.5630469e+08 | AB68: =IF(AA68>0,"Subiu",(IF(AA68<0,"Desceu","Estável"))) -> Desceu | AC68: =G68/100 -> -0.1433 | AD68: =C68/(AC68+1) -> 10.120229 | AE68: =(C68-AD68)*N68 -> -2.5630469e+08 | AF68: =IF(AE68>0,"Subiu",IF(AE68<0,"Desceu","Estável")) -> Desceu | AG68: =H68/100 -> -0.3452 | AH68: =C68/(AG68+1) -> 13.240684 | AI68: =(C68-AH68)*N68 -> -8.0779515e+08 | AJ68: =IF(AI68>0,"Subiu",IF(AI68<0,"Desceu","Estável")) -> Desceu
A69: CYRE3 | B69: 45317 | C69: 22.84 | D69: -1.38 | E69: 2.38 | F69: -5.15 | G69: -5.15 | H69: 60.09 | I69: 23.34 | J69: 22.62 | K69: 104,26 M | L69: =D69/100 -> -0.0138 | M69: =C69/(L69+1) -> 23.159603 | N69: =VLOOKUP(A69,'Total de Ações'!A:B,2,0) -> 265784616 | O69: =(C69-M69)*N69 -> -84945432 | P69: =IF(O69>0,"Subiu",if(O69<0,"Desceu","Estável")) -> Desceu | Q69: =VLOOKUP(A69,Ticker!A:B,2,0) -> Cyrela | R69: =VLOOKUP(Q69,ChatGpt!A:C,2,0) -> Construção Civil | S69: =VLOOKUP(Q69,ChatGpt!A:C,3,0) -> 60 | T69: =IF(S69>100,"Mais de 100", IF(S69<50,"Menos de 50","Entre 50 e 100")) -> Entre 50 e 100 | U69: =E69/100 -> 0.0238 | V69: =C69/(U69+1) -> 22.309045 | W69: =(C69-V69)*N69 -> 1.4111974e+08 | X69: =IF(W69>0,"Subiu",IF(W69<0,"Desceu","Estável")) -> Subiu | Y69: =F69/100 -> -0.0515 | Z69: =C69/(Y69+1) -> 24.080127 | AA69: =(C69-Z69)*N69 -> -3.2960655e+08 | AB69: =IF(AA69>0,"Subiu",(IF(AA69<0,"Desceu","Estável"))) -> Desceu | AC69: =G69/100 -> -0.0515 | AD69: =C69/(AC69+1) -> 24.080127 | AE69: =(C69-AD69)*N69 -> -3.2960655e+08 | AF69: =IF(AE69>0,"Subiu",IF(AE69<0,"Desceu","Estável")) -> Desceu | AG69: =H69/100 -> 0.6009 | AH69: =C69/(AG69+1) -> 14.266975 | AI69: =(C69-AH69)*N69 -> 2278578204 | AJ69: =IF(AI69>0,"Subiu",IF(AI69<0,"Desceu","Estável")) -> Subiu
A70: EMBR3 | B70: 45317 | C70: 22.4 | D70: -1.4 | E70: 5.02 | F70: 0.04 | G70: 0.04 | H70: 34.29 | I70: 22.92 | J70: 22.26 | K70: 60,86 M | L70: =D70/100 -> -0.014 | M70: =C70/(L70+1) -> 22.718053 | N70: =VLOOKUP(A70,'Total de Ações'!A:B,2,0) -> 734632705 | O70: =(C70-M70)*N70 -> -2.3365194e+08 | P70: =IF(O70>0,"Subiu",if(O70<0,"Desceu","Estável")) -> Desceu | Q70: =VLOOKUP(A70,Ticker!A:B,2,0) -> Embraer | R70: =VLOOKUP(Q70,ChatGpt!A:C,2,0) -> Aeronáutica | S70: =VLOOKUP(Q70,ChatGpt!A:C,3,0) -> 50 | T70: =IF(S70>100,"Mais de 100", IF(S70<50,"Menos de 50","Entre 50 e 100")) -> Entre 50 e 100 | U70: =E70/100 -> 0.0502 | V70: =C70/(U70+1) -> 21.329271 | W70: =(C70-V70)*N70 -> 7.8659282e+08 | X70: =IF(W70>0,"Subiu",IF(W70<0,"Desceu","Estável")) -> Subiu | Y70: =F70/100 -> 0.0004 | Z70: =C70/(Y70+1) -> 22.391044 | AA70: =(C70-Z70)*N70 -> 6579677.2 | AB70: =IF(AA70>0,"Subiu",(IF(AA70<0,"Desceu","Estável"))) -> Subiu | AC70: =G70/100 -> 0.0004 | AD70: =C70/(AC70+1) -> 22.391044 | AE70: =(C70-AD70)*N70 -> 6579677.2 | AF70: =IF(AE70>0,"Subiu",IF(AE70<0,"Desceu","Estável")) -> Subiu | AG70: =H70/100 -> 0.3429 | AH70: =C70/(AG70+1) -> 16.680319 | AI70: =(C70-AH70)*N70 -> 4201864935 | AJ70: =IF(AI70>0,"Subiu",IF(AI70<0,"Desceu","Estável")) -> Subiu
A71: NTCO3 | B71: 45317 | C71: 15.97 | D71: -1.41 | E71: -7.37 | F71: -5.45 | G71: -5.45 | H71: 23.51 | I71: 16.43 | J71: 15.84 | K71: 213,23 M | L71: =D71/100 -> -0.0141 | M71: =C71/(L71+1) -> 16.198397 | N71: =VLOOKUP(A71,'Total de Ações'!A:B,2,0) -> 846244302 | O71: =(C71-M71)*N71 -> -1.9328e+08 | P71: =IF(O71>0,"Subiu",if(O71<0,"Desceu","Estável")) -> Desceu | Q71: =VLOOKUP(A71,Ticker!A:B,2,0) -> Natura | R71: =VLOOKUP(Q71,ChatGpt!A:C,2,0) -> Beleza | S71: =VLOOKUP(Q71,ChatGpt!A:C,3,0) -> 50 | T71: =IF(S71>100,"Mais de 100", IF(S71<50,"Menos de 50","Entre 50 e 100")) -> Entre 50 e 100 | U71: =E71/100 -> -0.0737 | V71: =C71/(U71+1) -> 17.240635 | W71: =(C71-V71)*N71 -> -1075267446 | X71: =IF(W71>0,"Subiu",IF(W71<0,"Desceu","Estável")) -> Desceu | Y71: =F71/100 -> -0.0545 | Z71: =C71/(Y71+1) -> 16.890534 | AA71: =(C71-Z71)*N71 -> -7.7899674e+08 | AB71: =IF(AA71>0,"Subiu",(IF(AA71<0,"Desceu","Estável"))) -> Desceu | AC71: =G71/100 -> -0.0545 | AD71: =C71/(AC71+1) -> 16.890534 | AE71: =(C71-AD71)*N71 -> -7.7899674e+08 | AF71: =IF(AE71>0,"Subiu",IF(AE71<0,"Desceu","Estável")) -> Desceu | AG71: =H71/100 -> 0.2351 | AH71: =C71/(AG71+1) -> 12.930127 | AI71: =(C71-AH71)*N71 -> 2572475108 | AJ71: =IF(AI71>0,"Subiu",IF(AI71<0,"Desceu","Estável")) -> Subiu
A72: ASAI3 | B72: 45317 | C72: 13.8 | D72: -1.42 | E72: -3.5 | F72: 2 | G72: 2 | H72: -34.02 | I72: 14 | J72: 13.63 | K72: 79,67 M | L72: =D72/100 -> -0.0142 | M72: =C72/(L72+1) -> 13.998783 | N72: =VLOOKUP(A72,'Total de Ações'!A:B,2,0) -> 1349217892 | O72: =(C72-M72)*N72 -> -2.682012e+08 | P72: =IF(O72>0,"Subiu",if(O72<0,"Desceu","Estável")) -> Desceu | Q72: =VLOOKUP(A72,Ticker!A:B,2,0) -> Assaí | R72: =VLOOKUP(Q72,ChatGpt!A:C,2,0) -> Varejo | S72: =VLOOKUP(Q72,ChatGpt!A:C,3,0) -> 10 | T72: =IF(S72>100,"Mais de 100", IF(S72<50,"Menos de 50","Entre 50 e 100")) -> Menos de 50 | U72: =E72/100 -> -0.035 | V72: =C72/(U72+1) -> 14.300518 | W72: =(C72-V72)*N72 -> -6.7530802e+08 | X72: =IF(W72>0,"Subiu",IF(W72<0,"Desceu","Estável")) -> Desceu | Y72: =F72/100 -> 0.02 | Z72: =C72/(Y72+1) -> 13.529412 | AA72: =(C72-Z72)*N72 -> 3.6508249e+08 | AB72: =IF(AA72>0,"Subiu",(IF(AA72<0,"Desceu","Estável"))) -> Subiu | AC72: =G72/100 -> 0.02 | AD72: =C72/(AC72+1) -> 13.529412 | AE72: =(C72-AD72)*N72 -> 3.6508249e+08 | AF72: =IF(AE72>0,"Subiu",IF(AE72<0,"Desceu","Estável")) -> Subiu | AG72: =H72/100 -> -0.3402 | AH72: =C72/(AG72+1) -> 20.915429 | AI72: =(C72-AH72)*N72 -> -9600264005 | AJ72: =IF(AI72>0,"Subiu",IF(AI72<0,"Desceu","Estável")) -> Desceu
A73: B3SA3 | B73: 45317 | C73: 13.22 | D73: -1.56 | E73: -4.13 | F73: -8.58 | G73: -8.58 | H73: 3.88 | I73: 13.42 | J73: 13.18 | K73: 487,27 M | L73: =D73/100 -> -0.0156 | M73: =C73/(L73+1) -> 13.4295 | N73: =VLOOKUP(A73,'Total de Ações'!A:B,2,0) -> 5602790110 | O73: =(C73-M73)*N73 -> -1173785666 | P73: =IF(O73>0,"Subiu",if(O73<0,"Desceu","Estável")) -> Desceu | Q73: =VLOOKUP(A73,Ticker!A:B,2,0) -> B3 | R73: =VLOOKUP(Q73,ChatGpt!A:C,2,0) -> Finanças | S73: =VLOOKUP(Q73,ChatGpt!A:C,3,0) -> 10 | T73: =IF(S73>100,"Mais de 100", IF(S73<50,"Menos de 50","Entre 50 e 100")) -> Menos de 50 | U73: =E73/100 -> -0.0413 | V73: =C73/(U73+1) -> 13.789507 | W73: =(C73-V73)*N73 -> -3190826078 | X73: =IF(W73>0,"Subiu",IF(W73<0,"Desceu","Estável")) -> Desceu | Y73: =F73/100 -> -0.0858 | Z73: =C73/(Y73+1) -> 14.460731 | AA73: =(C73-Z73)*N73 -> -6951553659 | AB73: =IF(AA73>0,"Subiu",(IF(AA73<0,"Desceu","Estável"))) -> Desceu | AC73: =G73/100 -> -0.0858 | AD73: =C73/(AC73+1) -> 14.460731 | AE73: =(C73-AD73)*N73 -> -6951553659 | AF73: =IF(AE73>0,"Subiu",IF(AE73<0,"Desceu","Estável")) -> Desceu | AG73: =H73/100 -> 0.0388 | AH73: =C73/(AG73+1) -> 12.726223 | AI73: =(C73-AH73)*N73 -> 2766531332 | AJ73: =IF(AI73>0,"Subiu",IF(AI73<0,"Desceu","Estável")) -> Subiu
A74: HYPE3 | B74: 45317 | C74: 31.08 | D74: -1.61 | E74: -5.27 | F74: -13.06 | G74: -13.06 | H74: -27.52 | I74: 31.72 | J74: 30.91 | K74: 107,71 M | L74: =D74/100 -> -0.0161 | M74: =C74/(L74+1) -> 31.588576 | N74: =VLOOKUP(A74,'Total de Ações'!A:B,2,0) -> 409490388 | O74: =(C74-M74)*N74 -> -2.0825701e+08 | P74: =IF(O74>0,"Subiu",if(O74<0,"Desceu","Estável")) -> Desceu | Q74: =VLOOKUP(A74,Ticker!A:B,2,0) -> Hypera | R74: =VLOOKUP(Q74,ChatGpt!A:C,2,0) -> Farmacêutica | S74: =VLOOKUP(Q74,ChatGpt!A:C,3,0) -> 20 | T74: =IF(S74>100,"Mais de 100", IF(S74<50,"Menos de 50","Entre 50 e 100")) -> Menos de 50 | U74: =E74/100 -> -0.0527 | V74: =C74/(U74+1) -> 32.809036 | W74: =(C74-V74)*N74 -> -7.0802371e+08 | X74: =IF(W74>0,"Subiu",IF(W74<0,"Desceu","Estável")) -> Desceu | Y74: =F74/100 -> -0.1306 | Z74: =C74/(Y74+1) -> 35.748792 | AA74: =(C74-Z74)*N74 -> -1911825558 | AB74: =IF(AA74>0,"Subiu",(IF(AA74<0,"Desceu","Estável"))) -> Desceu | AC74: =G74/100 -> -0.1306 | AD74: =C74/(AC74+1) -> 35.748792 | AE74: =(C74-AD74)*N74 -> -1911825558 | AF74: =IF(AE74>0,"Subiu",IF(AE74<0,"Desceu","Estável")) -> Desceu | AG74: =H74/100 -> -0.2752 | AH74: =C74/(AG74+1) -> 42.880795 | AI74: =(C74-AH74)*N74 -> -4832312001 | AJ74: =IF(AI74>0,"Subiu",IF(AI74<0,"Desceu","Estável")) -> Desceu
A75: SMTO3 | B75: 45317 | C75: 28.2 | D75: -1.94 | E75: 0.36 | F75: -3.79 | G75: -3.79 | H75: 17.1 | I75: 28.97 | J75: 28.13 | K75: 73,55 M | L75: =D75/100 -> -0.0194 | M75: =C75/(L75+1) -> 28.757903 | N75: =VLOOKUP(A75,'Total de Ações'!A:B,2,0) -> 142377330 | O75: =(C75-M75)*N75 -> -79432786 | P75: =IF(O75>0,"Subiu",if(O75<0,"Desceu","Estável")) -> Desceu | Q75: =VLOOKUP(A75,Ticker!A:B,2,0) -> São Martinho | R75: =VLOOKUP(Q75,ChatGpt!A:C,2,0) -> Açúcar e Álcool | S75: =VLOOKUP(Q75,ChatGpt!A:C,3,0) -> 80 | T75: =IF(S75>100,"Mais de 100", IF(S75<50,"Menos de 50","Entre 50 e 100")) -> Entre 50 e 100 | U75: =E75/100 -> 0.0036 | V75: =C75/(U75+1) -> 28.098844 | W75: =(C75-V75)*N75 -> 14402298 | X75: =IF(W75>0,"Subiu",IF(W75<0,"Desceu","Estável")) -> Subiu | Y75: =F75/100 -> -0.0379 | Z75: =C75/(Y75+1) -> 29.310882 | AA75: =(C75-Z75)*N75 -> -1.5816448e+08 | AB75: =IF(AA75>0,"Subiu",(IF(AA75<0,"Desceu","Estável"))) -> Desceu | AC75: =G75/100 -> -0.0379 | AD75: =C75/(AC75+1) -> 29.310882 | AE75: =(C75-AD75)*N75 -> -1.5816448e+08 | AF75: =IF(AE75>0,"Subiu",IF(AE75<0,"Desceu","Estável")) -> Desceu | AG75: =H75/100 -> 0.171 | AH75: =C75/(AG75+1) -> 24.081981 | AI75: =(C75-AH75)*N75 -> 5.8631252e+08 | AJ75: =IF(AI75>0,"Subiu",IF(AI75<0,"Desceu","Estável")) -> Subiu
...

Sheet ChatGpt
A1: Nome da Empresa | B1: Segmento | C1: Idade em Anos
A2: Usiminas | B2: Siderurgia | C2: 60
A3: CSN Mineração | B3: Mineração | C3: 50
A4: Petrobras | B4: Petróleo e Gás | C4: 60
A5: Suzano | B5: Papel e Celulose | C5: 90
A6: CPFL Energia | B6: Energia | C6: 100
A7: PetroRio | B7: Petróleo e Gás | C7: Menos de 10
A8: Vale | B8: Mineração | C8: 70
A9: Multiplan | B9: Shopping Centers | C9: 50
A10: Itaú Unibanco | B10: Bancos | C10: 10
A11: Rede D'Or | B11: Saúde | C11: 40
A12: Braskem | B12: Petroquímica | C12: 10
A13: Azul | B13: Transporte Aéreo | C13: 10
A14: 3R Petroleum | B14: Petróleo e Gás | C14: Menos de 10
A15: Equatorial Energia | B15: Energia | C15: 20
A16: Siderúrgica Nacional | B16: Siderurgia | C16: 70
A17: YDUQS | B17: Educação | C17: 50
A18: Ultrapar | B18: Distribuição | C18: 80
A19: MRV | B19: Construção Civil | C19: 40
A20: Arezzo | B20: Moda | C20: 40
A21: Banco Bradesco | B21: Bancos | C21: 70
A22: Minerva | B22: Alimentos | C22: 90
A23: Grupo Pão de Açúcar | B23: Alimentos | C23: 70
A24: BRF | B24: Alimentos | C24: 80
A25: Vivo | B25: Telecomunicações | C25: 20
A26: Rumo | B26: Logística | C26: 10
... A60: IRB Brasil RE | B60: Seguros | C60: 80
A61: Petz | B61: Varejo | C61: Menos de 10
A62: EZTEC | B62: Construção Civil | C62: 40
A63: Fleury | B63: Saúde | C63: 50
A64: Grupo Soma | B64: Varejo | C64: 20
A65: Alpargatas | B65: Calçados | C65: 100
A66: Cyrela | B66: Construção Civil | C66: 60
A67: Embraer | B67: Aeronáutica | C67: 50
A68: Natura | B68: Beleza | C68: 50
A69: Assaí | B69: Varejo | C69: 10
A70: B3 | B70: Finanças | C70: 10
A71: Hypera | B71: Farmacêutica | C71: 20
A72: São Martinho | B72: Açúcar e Álcool | C72: 80
A73: Hapvida | B73: Saúde | C73: 40
...

Sheet Total de Ações
A1: Código | B1: Qtde. Teórica
A2: RRRP3 | B2: 235665566
A3: ALOS3 | B3: 532616595
A4: ALPA4 | B4: 176733968
A5: ABEV3 | B5: 4394245879
A6: ARZZ3 | B6: 62305891
A7: ASAI3 | B7: 1349217892
A8: AZUL4 | B8: 327593725
A9: B3SA3 | B9: 5602790110
A10: BBSE3 | B10: 671750768
A11: BBDC3 | B11: 1500728902
A12: BBDC4 | B12: 5146576868
A13: BRAP4 | B13: 251003438
... A90: Redutor | B90: 17047851

Sheet Ticker
A1: Ticker | B1: Nome
A2: MGLU3 | B2: Magazine Luiza
A3: HAPV3 | B3: Hapvida
A4: PETR4 | B4: Petrobras
A5: B3SA3 | B5: B3
A6: USIM5 | B6: Usiminas
A7: CVCB3 | B7: CVC
A8: CIEL3 | B8: Cielo
A9: VALE3 | B9: Vale
A10: GOLL4 | B10: GOL
A11: BBDC4 | B11: Banco Bradesco
A12: AZUL4 | B12: Azul
... A536: MMAQ4 | B536: Minasmáquinas

Sheet Análises
A1: Maior | B1: =MAX(Principal!O:O) -> 4762926995 | C1: =VLOOKUP(B1,Principal!O:R,3,0) -> Vale
A2: Menor | B2: =MIN(Principal!O:O) -> -1807432634 | C2: =VLOOKUP(B2,Principal!O:R,3,0) -> Localiza
A3: Média | B3: =AVERAGE(Principal!O:O) -> 1.6519021e+08
A4: Média de quem subiu | B4: =AVERAGEIF(Principal!P:P,"Subiu",Principal!O:O) -> 4.4816425e+08
A5: Média de quem desceu | B5: =AVERAGEIF(Principal!P:P,"Desceu",Principal!O:O) -> -1.8110914e+08
A10: =IFERROR(__xludf.DUMMYFUNCTION("UNIQUE(Principal!R:R)"),"Segmento") -> Segmento | B10: Variação por segmento | C10: Variação de quem subiu
A11: =IFERROR(__xludf.DUMMYFUNCTION("""COMPUTED_VALUE"""),"Siderurgia") -> Siderurgia | B11: =SUMIF(Principal!R:R,A11,Principal!O:O) -> 4.8993593e+08 | C11: =SUMIFS(Principal!O:O,Principal!R:R,A11,Principal!P:P,"Subiu") -> 4.8993593e+08
A12: =IFERROR(__xludf.DUMMYFUNCTION("""COMPUTED_VALUE"""),"Mineração") -> Mineração | B12: =SUMIF(Principal!R:R,A12,Principal!O:O) -> 4940442966 | C12: =SUMIFS(Principal!O:O,Principal!R:R,A12,Principal!P:P,"Subiu") -> 4940442966
A13: =IFERROR(__xludf.DUMMYFUNCTION("""COMPUTED_VALUE"""),"Petróleo e Gás") -> Petróleo e Gás | B13: =SUMIF(Principal!R:R,A13,Principal!O:O) -> 6093288832 | C13: =SUMIFS(Principal!O:O,Principal!R:R,A13,Principal!P:P,"Subiu") -> 6093288832
A14: =IFERROR(__xludf.DUMMYFUNCTION("""COMPUTED_VALUE"""),"Papel e Celulose") -> Papel e Celulose | B14: =SUMIF(Principal!R:R,A14,Principal!O:O) -> 7.2294628e+08 | C14: =SUMIFS(Principal!O:O,Principal!R:R,A14,Principal!P:P,"Subiu") -> 7.2294628e+08
A15: =IFERROR(__xludf.DUMMYFUNCTION("""COMPUTED_VALUE"""),"Energia") -> Energia | B15: =SUMIF(Principal!R:R,A15,Principal!O:O) -> -1.2060189e+08 | C15: =SUMIFS(Principal!O:O,Principal!R:R,A15,Principal!P:P,"Subiu") -> 8.3918485e+08
A16: =IFERROR(__xludf.DUMMYFUNCTION("""COMPUTED_VALUE"""),"Shopping Centers") -> Shopping Centers | B16: =SUMIF(Principal!R:R,A16,Principal!O:O) -> 1.1773268e+08 | C16: =SUMIFS(Principal!O:O,Principal!R:R,A16,Principal!P:P,"Subiu") -> 1.1773268e+08
A17: =IFERROR(__xludf.DUMMYFUNCTION("""COMPUTED_VALUE"""),"Bancos") -> Bancos | B17: =SUMIF(Principal!R:R,A17,Principal!O:O) -> 4156604263 | C17: =SUMIFS(Principal!O:O,Principal!R:R,A17,Principal!P:P,"Subiu") -> 4156604263
A18: =IFERROR(__xludf.DUMMYFUNCTION("""COMPUTED_VALUE"""),"Saúde") -> Saúde | B18: =SUMIF(Principal!R:R,A18,Principal!O:O) -> 2.6267394e+08 | C18: =SUMIFS(Principal!O:O,Principal!R:R,A18,Principal!P:P,"Subiu") -> 6.5627038e+08
A19: =IFERROR(__xludf.DUMMYFUNCTION("""COMPUTED_VALUE"""),"Petroquímica") -> Petroquímica | B19: =SUMIF(Principal!R:R,A19,Principal!O:O) -> 69054318 | C19: =SUMIFS(Principal!O:O,Principal!R:R,A19,Principal!P:P,"Subiu") -> 69054318
A20: =IFERROR(__xludf.DUMMYFUNCTION("""COMPUTED_VALUE"""),"Transporte Aéreo") -> Transporte Aéreo | B20: =SUMIF(Principal!R:R,A20,Principal!O:O) -> -37540997 | C20: =SUMIFS(Principal!O:O,Principal!R:R,A20,Principal!P:P,"Subiu") -> 65452206
A21: =IFERROR(__xludf.DUMMYFUNCTION("""COMPUTED_VALUE"""),"Educação") -> Educação | B21: =SUMIF(Principal!R:R,A21,Principal!O:O) -> 54641872 | C21: =SUMIFS(Principal!O:O,Principal!R:R,A21,Principal!P:P,"Subiu") -> 72295839
A22: =IFERROR(__xludf.DUMMYFUNCTION("""COMPUTED_VALUE"""),"Distribuição") -> Distribuição | B22: =SUMIF(Principal!R:R,A22,Principal!O:O) -> 388705224 | C22: =SUMIFS(Principal!O:O,Principal!R:R,A22,Principal!P:P,"Subiu") -> 388705224
A23: =IFERROR(__xludf.DUMMYFUNCTION("""COMPUTED_VALUE"""),"Construção Civil") -> Construção Civil | B23: =SUMIF(Principal!R:R,A23,Principal!O:O) -> -61087402 | C23: =SUMIFS(Principal!O:O,Principal!R:R,A23,Principal!P:P,"Subiu") -> 37525872
A24: =IFERROR(__xludf.DUMMYFUNCTION("""COMPUTED_VALUE"""),"Moda") -> Moda | B24: =SUMIF(Principal!R:R,A24,Principal!O:O) -> 41021792 | C24: =SUMIFS(Principal!O:O,Principal!R:R,A24,Principal!P:P,"Subiu") -> 41021792
A25: =IFERROR(__xludf.DUMMYFUNCTION("""COMPUTED_VALUE"""),"Alimentos") -> Alimentos | B25: =SUMIF(Principal!R:R,A25,Principal!O:O) -> 4.141746e+08 | C25: =SUMIFS(Principal!O:O,Principal!R:R,A25,Principal!P:P,"Subiu") -> 4.141746e+08
A26: =IFERROR(__xludf.DUMMYFUNCTION("""COMPUTED_VALUE"""),"Telecomunicações") -> Telecomunicações | B26: =SUMIF(Principal!R:R,A26,Principal!O:O) -> 2.5611856e+08 | C26: =SUMIFS(Principal!O:O,Principal!R:R,A26,Principal!P:P,"Subiu") -> 2.9293811e+08
A27: =IFERROR(__xludf.DUMMYFUNCTION("""COMPUTED_VALUE"""),"Logística") -> Logística | B27: =SUMIF(Principal!R:R,A27,Principal!O:O) -> 2.3390267e+08 | C27: =SUMIFS(Principal!O:O,Principal!R:R,A27,Principal!P:P,"Subiu") -> 2.3390267e+08
A28: =IFERROR(__xludf.DUMMYFUNCTION("""COMPUTED_VALUE"""),"Serviços Financeiros") -> Serviços Financeiros | B28: =SUMIF(Principal!R:R,A28,Principal!O:O) -> 43657683 | C28: =SUMIFS(Principal!O:O,Principal!R:R,A28,Principal!P:P,"Subiu") -> 43657683
A29: =IFERROR(__xludf.DUMMYFUNCTION("""COMPUTED_VALUE"""),"Tecnologia") -> Tecnologia | B29: =SUMIF(Principal!R:R,A29,Principal!O:O) -> 6067508.9 | C29: =SUMIFS(Principal!O:O,Principal!R:R,A29,Principal!P:P,"Subiu") -> 15598887
A30: =IFERROR(__xludf.DUMMYFUNCTION("""COMPUTED_VALUE"""),"Varejo") -> Varejo | B30: =SUMIF(Principal!R:R,A30,Principal!O:O) -> -8.0957219e+08 | C30: =SUMIFS(Principal!O:O,Principal!R:R,A30,Principal!P:P,"Subiu") -> 28493619
A31: =IFERROR(__xludf.DUMMYFUNCTION("""COMPUTED_VALUE"""),"Bebidas") -> Bebidas | B31: =SUMIF(Principal!R:R,A31,Principal!O:O) -> 0 | C31: =SUMIFS(Principal!O:O,Principal!R:R,A31,Principal!P:P,"Subiu") -> 0
A32: =IFERROR(__xludf.DUMMYFUNCTION("""COMPUTED_VALUE"""),"Seguros") -> Seguros | B32: =SUMIF(Principal!R:R,A32,Principal!O:O) -> -26297880 | C32: =SUMIFS(Principal!O:O,Principal!R:R,A32,Principal!P:P,"Subiu") -> 0
A33: =IFERROR(__xludf.DUMMYFUNCTION("""COMPUTED_VALUE"""),"Água e Saneamento") -> Água e Saneamento | B33: =SUMIF(Principal!R:R,A33,Principal!O:O) -> -15725679 | C33: =SUMIFS(Principal!O:O,Principal!R:R,A33,Principal!P:P,"Subiu") -> 0
A34: =IFERROR(__xludf.DUMMYFUNCTION("""COMPUTED_VALUE"""),"Agricultura") -> Agricultura | B34: =SUMIF(Principal!R:R,A34,Principal!O:O) -> -9468663.7 | C34: =SUMIFS(Principal!O:O,Principal!R:R,A34,Principal!P:P,"Subiu") -> 0
A35: =IFERROR(__xludf.DUMMYFUNCTION("""COMPUTED_VALUE"""),"Infraestrutura") -> Infraestrutura | B35: =SUMIF(Principal!R:R,A35,Principal!O:O) -> -39743554 | C35: =SUMIFS(Principal!O:O,Principal!R:R,A35,Principal!P:P,"Subiu") -> 0
A36: =IFERROR(__xludf.DUMMYFUNCTION("""COMPUTED_VALUE"""),"Calçados") -> Calçados | B36: =SUMIF(Principal!R:R,A36,Principal!O:O) -> -21126374 | C36: =SUMIFS(Principal!O:O,Principal!R:R,A36,Principal!P:P,"Subiu") -> 0
A37: =IFERROR(__xludf.DUMMYFUNCTION("""COMPUTED_VALUE"""),"Aeronáutica") -> Aeronáutica | B37: =SUMIF(Principal!R:R,A37,Principal!O:O) -> -2.3365194e+08 | C37: =SUMIFS(Principal!O:O,Principal!R:R,A37,Principal!P:P,"Subiu") -> 0
A38: =IFERROR(__xludf.DUMMYFUNCTION("""COMPUTED_VALUE"""),"Beleza") -> Beleza | B38: =SUMIF(Principal!R:R,A38,Principal!O:O) -> -1.9328e+08 | C38: =SUMIFS(Principal!O:O,Principal!R:R,A38,Principal!P:P,"Subiu") -> 0
A39: =IFERROR(__xludf.DUMMYFUNCTION("""COMPUTED_VALUE"""),"Finanças") -> Finanças | B39: =SUMIF(Principal!R:R,A39,Principal!O:O) -> -1173785666 | C39: =SUMIFS(Principal!O:O,Principal!R:R,A39,Principal!P:P,"Subiu") -> 0
A40: =IFERROR(__xludf.DUMMYFUNCTION("""COMPUTED_VALUE"""),"Farmacêutica") -> Farmacêutica | B40: =SUMIF(Principal!R:R,A40,Principal!O:O) -> -2.0825701e+08 | C40: =SUMIFS(Principal!O:O,Principal!R:R,A40,Principal!P:P,"Subiu") -> 0
A41: =IFERROR(__xludf.DUMMYFUNCTION("""COMPUTED_VALUE"""),"Açúcar e Álcool") -> Açúcar e Álcool | B41: =SUMIF(Principal!R:R,A41,Principal!O:O) -> -79432786 | C41: =SUMIFS(Principal!O:O,Principal!R:R,A41,Principal!P:P,"Subiu") -> 0
A42: =IFERROR(__xludf.DUMMYFUNCTION("""COMPUTED_VALUE"""),"Aluguel de Carros") -> Aluguel de Carros | B42: =SUMIF(Principal!R:R,A42,Principal!O:O) -> -1807432634 | C42: =SUMIFS(Principal!O:O,Principal!R:R,A42,Principal!P:P,"Subiu") -> 0
